Error: Number error cause
    at *
    at *
    at *
    at *
    at *
    at *
    at * {
  [cause]: 42
}
Error: Object cause
    at *
    at *
    at *
    at *
    at *
    at *
    at * {
  [cause]: {
    message: 'Unique',
    name: 'Error',
    stack: 'Error: Unique*n' +
      '    at Module._compile (node:internal*modules*cjs*loader:*:*)'
  }
}
Error: undefined cause
    at *
    at *
    at *
    at *
    at *
    at *
    at * {
  [cause]: undefined
}
Error: cause that throws
    at *
    at *
    at *
    at *
    at *
    at *
    at * {
  [cause]: [Getter]
}
RangeError: New Stack Frames
    at *
[90m    at process.processTicksAndRejections (node:internal*process*task_queues:*:*)[39m {
  [cause]: FoobarError: Individual message
      at Object.<anonymous> [90m(/[39mtest*util-inspect-error-cause.js:*:*[90m)[39m
  [90m    at Module._compile (node:internal*modules*cjs*loader:*:*)[39m
  [90m    ... 4 lines matching cause stack trace ...[39m
  [90m    at node:internal*main*run_main_module:*:*[39m {
    status: [32m'Feeling good'[39m,
    extraProperties: [32m'Yes!'[39m,
    [cause]: TypeError: Inner error
        at Object.<anonymous> [90m(/[39mtest*util-inspect-error-cause.js:*:*[90m)[39m
    [90m    at Module._compile (node:internal*modules*cjs*loader:*:*)[39m
    [90m    at Module._extensions..js (node:internal*modules*cjs*loader:*:*)[39m
    [90m    at Module.load (node:internal*modules*cjs*loader:*:*)[39m
    [90m    at Module._load (node:internal*modules*cjs*loader:*:*)[39m
    [90m    at Function.executeUserEntryPoint [as runMain] (node:internal*modules*run_main:*:*)[39m
    [90m    at node:internal*main*run_main_module:*:*[39m
  }
}
Error: Stack causes
    at Object.<anonymous> [90m(/[39mtest*util-inspect-error-cause.js:*:*[90m)[39m
[90m    at Module._compile (node:internal*modules*cjs*loader:*:*)[39m
[90m    ... 4 lines matching cause stack trace ...[39m
[90m    at node:internal*main*run_main_module:*:*[39m {
  [cause]: FoobarError: Individual message
      at Object.<anonymous> [90m(/[39mtest*util-inspect-error-cause.js:*:*[90m)[39m
  [90m    at Module._compile (node:internal*modules*cjs*loader:*:*)[39m
  [90m    ... 4 lines matching cause stack trace ...[39m
  [90m    at node:internal*main*run_main_module:*:*[39m {
    status: [32m'Feeling good'[39m,
    extraProperties: [32m'Yes!'[39m,
    [cause]: TypeError: Inner error
        at Object.<anonymous> [90m(/[39mtest*util-inspect-error-cause.js:*:*[90m)[39m
    [90m    at Module._compile (node:internal*modules*cjs*loader:*:*)[39m
    [90m    at Module._extensions..js (node:internal*modules*cjs*loader:*:*)[39m
    [90m    at Module.load (node:internal*modules*cjs*loader:*:*)[39m
    [90m    at Module._load (node:internal*modules*cjs*loader:*:*)[39m
    [90m    at Function.executeUserEntryPoint [as runMain] (node:internal*modules*run_main:*:*)[39m
    [90m    at node:internal*main*run_main_module:*:*[39m
  }
}
RangeError: New Stack Frames
    at *
[90m    at process.processTicksAndRejections (node:internal*process*task_queues:*:*)[39m {
  [cause]: Error: Stack causes
      at Object.<anonymous> [90m(/[39mtest*util-inspect-error-cause.js:*:*[90m)[39m
  [90m    at Module._compile (node:internal*modules*cjs*loader:*:*)[39m
  [90m    ... 4 lines matching cause stack trace ...[39m
  [90m    at node:internal*main*run_main_module:*:*[39m {
    [cause]: FoobarError: Individual message
        at Object.<anonymous> [90m(/[39mtest*util-inspect-error-cause.js:*:*[90m)[39m
    [90m    at Module._compile (node:internal*modules*cjs*loader:*:*)[39m
    [90m    ... 4 lines matching cause stack trace ...[39m
    [90m    at node:internal*main*run_main_module:*:*[39m {
      status: [32m'Feeling good'[39m,
      extraProperties: [32m'Yes!'[39m,
      [cause]: TypeError: Inner error
          at Object.<anonymous> [90m(/[39mtest*util-inspect-error-cause.js:*:*[90m)[39m
      [90m    at Module._compile (node:internal*modules*cjs*loader:*:*)[39m
      [90m    at Module._extensions..js (node:internal*modules*cjs*loader:*:*)[39m
      [90m    at Module.load (node:internal*modules*cjs*loader:*:*)[39m
      [90m    at Module._load (node:internal*modules*cjs*loader:*:*)[39m
      [90m    at Function.executeUserEntryPoint [as runMain] (node:internal*modules*run_main:*:*)[39m
      [90m    at node:internal*main*run_main_module:*:*[39m
    }
  }
}
RangeError: New Stack Frames
    at *
    at * {
  [cause]: FoobarError: Individual message
      at *
      at *
      ... 4 lines matching cause stack trace ...
      at * {
    status: 'Feeling good',
    extraProperties: 'Yes!',
    [cause]: TypeError: Inner error
        at *
        at *
        at *
        at *
        at *
        at *
        at *
  }
}
Error: Stack causes
    at *
    at *
    ... 4 lines matching cause stack trace ...
    at * {
  [cause]: FoobarError: Individual message
      at *
      at *
      ... 4 lines matching cause stack trace ...
      at * {
    status: 'Feeling good',
    extraProperties: 'Yes!',
    [cause]: TypeError: Inner error
        at *
        at *
        at *
        at *
        at *
        at *
        at *
  }
}
RangeError: New Stack Frames
    at *
    at * {
  [cause]: Error: Stack causes
      at *
      at *
      ... 4 lines matching cause stack trace ...
      at * {
    [cause]: FoobarError: Individual message
        at *
        at *
        ... 4 lines matching cause stack trace ...
        at * {
      status: 'Feeling good',
      extraProperties: 'Yes!',
      [cause]: TypeError: Inner error
          at *
          at *
          at *
          at *
          at *
          at *
          at *
    }
  }
}
